package com.xxf.arch.rxjava.lifecycle.internal;

import java.util.concurrent.CancellationException;

import io.reactivex.rxjava3.core.Completable;
import io.reactivex.rxjava3.exceptions.Exceptions;
import io.reactivex.rxjava3.functions.Function;
import io.reactivex.rxjava3.functions.Predicate;


final class Functions {

    static final Function<Throwable, Boolean> RESUME_FUNCTION = new Function<Throwable, Boolean>() {
        @Override
        public Boolean apply(Throwable throwable) throws Exception {
            if (throwable instanceof OutsideLifecycleException) {
                return true;
            }

            //noinspection ThrowableResultOfMethodCallIgnored
            Exceptions.propagate(throwable);
            return false;
        }
    };

    static final Predicate<Boolean> SHOULD_COMPLETE = new Predicate<Boolean>() {
        @Override
        public boolean test(Boolean shouldComplete) throws Exception {
            return shouldComplete;
        }
    };

    static final Function<Object, Completable> CANCEL_COMPLETABLE = new Function<Object, Completable>() {
        @Override
        public Completable apply(Object ignore) throws Exception {
            return Completable.error(new CancellationException());
        }
    };

    private Functions() {
        throw new AssertionError("No instances!");
    }
}
